<?xml version="1.0"?>
<robot xmlns:xacro="http://www.ros.org/wiki/xacro" name="car_4ws">

  <xacro:property name="chassis_len" value="0.4"/>
  <xacro:property name="chassis_width" value="0.2"/>
  <xacro:property name="chassis_height" value="0.1"/>
  <xacro:property name="wheel_radius" value="0.05"/>
  <xacro:property name="wheel_thick" value="0.04"/>

  <xacro:macro name="box_inertia" params="m w l h">
    <inertial>
      <mass value="${m}"/>
      <inertia ixx="${(m/12)*(h*h+l*l)}" ixy="0" ixz="0" iyy="${(m/12)*(w*w+l*l)}" iyz="0" izz="${(m/12)*(w*w+h*h)}"/>
    </inertial>
  </xacro:macro>

  <xacro:macro name="cylinder_inertia" params="m r h">
    <inertial>
      <mass value="${m}"/>
      <inertia ixx="${(m/12)*(3*r*r+h*h)}" ixy="0" ixz="0" iyy="${(m/12)*(3*r*r+h*h)}" iyz="0" izz="${(m/2)*(r*r)}"/>
    </inertial>
  </xacro:macro>

  <material name="blue"><color rgba="0.0 0.2 0.8 1.0"/></material>
  <link name="chassis">
    <visual><geometry><box size="${chassis_len} ${chassis_width} ${chassis_height}"/></geometry><material name="blue"/></visual>
    <collision><geometry><box size="${chassis_len} ${chassis_width} ${chassis_height}"/></geometry></collision>
    <xacro:box_inertia m="5.0" w="${chassis_width}" l="${chassis_len}" h="${chassis_height}"/>
  </link>

  <material name="black"><color rgba="0.1 0.1 0.1 1.0"/></material>
  <xacro:macro name="swerve_wheel" params="prefix x_pos y_pos">
    <link name="${prefix}_steer_link"><xacro:cylinder_inertia m="0.1" r="0.02" h="0.02"/></link>
    <joint name="${prefix}_steer_joint" type="revolute">
      <parent link="chassis"/><child link="${prefix}_steer_link"/>
      <origin xyz="${x_pos} ${y_pos} 0" rpy="0 0 0"/><axis xyz="0 0 1"/>
      <limit lower="-0.785" upper="0.785" effort="10" velocity="1.5"/>
    </joint>

    <link name="${prefix}_wheel_link">
      <visual><geometry><cylinder radius="${wheel_radius}" length="${wheel_thick}"/></geometry><origin xyz="0 0 0" rpy="1.5708 0 0"/><material name="black"/></visual>
      <collision><geometry><cylinder radius="${wheel_radius}" length="${wheel_thick}"/></geometry><origin xyz="0 0 0" rpy="1.5708 0 0"/></collision>
      <xacro:cylinder_inertia m="1.0" r="${wheel_radius}" h="${wheel_thick}"/>
    </link>
    <joint name="${prefix}_wheel_joint" type="continuous">
      <parent link="${prefix}_steer_link"/><child link="${prefix}_wheel_link"/>
      <origin xyz="0 0 0" rpy="0 0 0"/><axis xyz="0 1 0"/>
      <limit effort="5" velocity="25"/>
    </joint>
  </xacro:macro>

  <xacro:swerve_wheel prefix="fl" x_pos="0.15" y_pos="0.12"/>
  <xacro:swerve_wheel prefix="fr" x_pos="0.15" y_pos="-0.12"/>
  <xacro:swerve_wheel prefix="rl" x_pos="-0.15" y_pos="0.12"/>
  <xacro:swerve_wheel prefix="rr" x_pos="-0.15" y_pos="-0.12"/>

  <link name="lidar_link">
    <visual><geometry><cylinder radius="0.04" length="0.05"/></geometry></visual>
    <collision><geometry><cylinder radius="0.04" length="0.05"/></geometry></collision>
    <xacro:cylinder_inertia m="0.2" r="0.04" h="0.05"/>
  </link>
  <joint name="lidar_joint" type="fixed">
    <parent link="chassis"/><child link="lidar_link"/><origin xyz="0 0 0.08" rpy="0 0 0"/>
  </joint>

  <gazebo reference="lidar_link">
    <sensor name="lidar" type="ray">
      <always_on>true</always_on><visualize>true</visualize><update_rate>10</update_rate>
      <ray>
        <scan><horizontal><samples>360</samples><resolution>1</resolution><min_angle>-3.14</min_angle><max_angle>3.14</max_angle></horizontal></scan>
        <range><min>0.12</min><max>10.0</max><resolution>0.01</resolution></range>
      </ray>
      <plugin name="gazebo_ros_lidar_controller" filename="libgazebo_ros_ray_sensor.so">
        <ros><remapping>~/out:=scan</remapping></ros>
        <output_type>sensor_msgs/LaserScan</output_type>
        <frame_name>lidar_link</frame_name>
      </plugin>
    </sensor>
  </gazebo>

  <ros2_control name="GazeboSystem" type="system">
    <hardware><plugin>gazebo_ros2_control/GazeboSystem</plugin></hardware>
    <xacro:macro name="swerve_transmission" params="prefix">
      <joint name="${prefix}_steer_joint">
        <command_interface name="position"/><state_interface name="position"/>
      </joint>
      <joint name="${prefix}_wheel_joint">
        <command_interface name="velocity"/><state_interface name="velocity"/><state_interface name="position"/>
      </joint>
    </xacro:macro>
    <xacro:swerve_transmission prefix="fl"/>
    <xacro:swerve_transmission prefix="fr"/>
    <xacro:swerve_transmission prefix="rl"/>
    <xacro:swerve_transmission prefix="rr"/>
  </ros2_control>

  <gazebo>
    <plugin filename="libgazebo_ros2_control.so" name="gazebo_ros2_control">
      <parameters>/home/kenji/Desktop/my_4ws_robot/config/controllers.yaml</parameters>
    </plugin>
  </gazebo>
  
  <gazebo>
    <plugin name="gazebo_ros_p3d" filename="libgazebo_ros_p3d.so">
      <ros>
        <namespace>/</namespace>
        <remapping>odom:=/ground_truth</remapping>
      </ros>
      <body_name>chassis</body_name> 
      <frame_name>world</frame_name>
      <update_rate>50.0</update_rate>
      <xyz_offset>0 0 0</xyz_offset>
      <rpy_offset>0 0 0</rpy_offset>
      <gaussian_noise>0.0</gaussian_noise>
    </plugin>
  </gazebo>

</robot>